<?xml version="1.0"?>
<robot xmlns:xacro="http://www.ros.org/wiki/xacro" name="rover">

<link name="world">
    
</link>


<!-- defining chassis -->
<link name="base_link">
    <inertial>
        <origin xyz="0.0 0.0 0.0" rpy="0.0 0.0 0.0"/>
        <mass value="1.0"/>
        <inertia ixx="0.0" ixy="0.0" ixz="0.0" iyy="0.0" iyz="0.0" izz="0.0"/>
    </inertial>
    <visual name="">
        <origin xyz="0.0 0.0 0.0" rpy="0.0 0.0 0.0"/>
        <geometry>
            <box size="0.8 0.7 0.1"/>
        </geometry>
        <material name="">
            <color rgba="1.0 0.0 0.0 1.0"/>
        </material>
    </visual>
    <collision>
        <origin xyz="0.0 0.0 0.0" rpy="0.0 0.0 0.0"/>
        <geometry>
            <box size="0.0 0.0 0.0"/>
        </geometry>
    </collision>
</link>

<gazebo reference="base_link">
    <material>Gazebo/Red</material>
</gazebo>

<joint name="base_joint" type="fixed">
    <origin xyz="0.0 0.0 0.135" rpy="0.0 0.0 0.0"/>
    <parent link="world"/>
    <child link="base_link"/>
    <axis xyz="0.0 0.0 0.0"/>
    <limit lower="0.0" upper="0.0" effort="0.0" velocity="0.0"/>
</joint>

<!-- xacros:format to call multiple blocks togather; macro:code block -->

<xacro:macro name="wheels" params="name x y">

    <link name="wheel_${name}">
        <inertial>
            <origin xyz="0.0 0.0 0.0" rpy="0.0 0.0 0.0"/>
            <mass value="0.5"/>   <!--mass important for gazebo or wont spawn-->
            <inertia ixx="0.0" ixy="0.0" ixz="0.0" iyy="0.0" iyz="0.0" izz="0.0"/>
        </inertial>
        <visual name="">
            <origin xyz="0.0 0.0 0.0" rpy="0.0 0.0 0.0"/>
            <geometry>
            <!-- turtlebots wheel mesh off the internet -->
                <mesh filename="package://mobile_robot/meshes/left_tire.stl" scale="0.005 0.005 0.005"/>
            </geometry>
            <material name="black">
                <color rgba="0.0 0.0 0.0 1.0"/>
            </material>
        </visual>
        <collision>
            <origin xyz="0.0 0.0 0.0" rpy="0.0 0.0 0.0"/>
            <geometry>
                <mesh filename="package://mobile_robot/meshes/left_tire.stl" scale="0.005 0.005 0.005"/>
            </geometry>
        </collision>
    </link>

    <gazebo reference="wheel_${name}">
        <material>Gazebo/Black</material>

    </gazebo>

    <joint name="${name}_joint" type="continuous">
        <origin xyz="${x} ${y} 0.0" rpy="0.0 0.0 0.0"/>
        <parent link="base_link"/>
        <child link="wheel_${name}"/>
        <axis xyz="0 1 0"/>
        <limit lower="0.0" upper="0.0" effort="0.0" velocity="0.0"/>
    </joint>
    
</xacro:macro>

<xacro:wheels name="left_rear" x="-0.25" y="-0.4"/>
<xacro:wheels name="left_front" x="0.25" y="-0.4"/>
<xacro:wheels name="right_rear" x="-0.25" y="0.4"/>
<xacro:wheels name="right_front" x="0.25" y="0.4"/>



</robot>
